<?xml version="1.0" ?>
<robot name="b400wheelchair" xmlns:xacro="http://www.ros.org/wiki/xacro">

<xacro:include filename="$(find nararobot)/urdf/materials.xacro" />
<xacro:include filename="$(find nararobot)/urdf/b400wheelchair.trans" />
<xacro:include filename="$(find nararobot)/urdf/b400wheelchair.gazebo" />

<link name="base_footprint"></link>

<link name="base_link">
  <inertial>
    <origin rpy="0 0 0" xyz="-0.1246993365714202 0.001634834027716904 0.34670147890046166"/>
    <mass value="556.936742489036"/>
    <inertia ixx="37.878676" ixy="0.043194" ixz="0.816109" iyy="51.604731" iyz="0.127941" izz="29.510251"/>
  </inertial>
  <visual>
    <origin rpy="0 0 0" xyz="0.23 0 0"/>
    <geometry>
      <mesh filename="package://nararobot/meshes/base_link.stl" scale="0.001 0.001 0.001"/>
    </geometry>
    <material name="silver"/>
  </visual>
  <collision>
    <origin rpy="0 0 0" xyz="0 0 0"/>
    <geometry>
      <mesh filename="package://nararobot/meshes/base_link.stl" scale="0.001 0.001 0.001"/>
    </geometry>
  </collision>
</link>


<link name="camera_link">
  <inertial>
    <origin rpy="0 0 0" xyz="0 0 0"/>
    <mass value="0.15"/>
    <inertia ixx="1e-6" ixy="0" ixz="0" iyy="1e-6" iyz="0" izz="1e-6" />
  </inertial>

  <visual>
    <origin rpy="0 0 0" xyz="0 0 0"/>
    <geometry>
      <mesh filename="package://nararobot/meshes/ZED2.stl" scale="0.001 0.001 0.001"/>
    </geometry>
    <material name="silver"/>
  </visual>

  <collision>
    <origin rpy="0 0 0" xyz="0 0 0"/>
    <geometry>
      <mesh filename="package://nararobot/meshes/ZED2.stl" scale="0.001 0.001 0.001"/>
    </geometry>
  </collision>
</link>

<link name="LeftBwheel_1">
  <inertial>
    <origin rpy="0 0 0" xyz="0.0 -0.009938723135145988 0.0"/>
    <mass value="38.72535292582958"/>
    <inertia ixx="0.371681" ixy="0.0" ixz="-0.0" iyy="0.708374" iyz="0.0" izz="0.371681"/>
  </inertial>
  <visual>
    <origin rpy="0 0 0" xyz="0.25395 -0.25952 -0.1778"/>
    <geometry>
      <mesh filename="package://nararobot/meshes/LeftBwheel_1.stl" scale="0.001 0.001 0.001"/>
    </geometry>
    <material name="silver"/>
  </visual>
  <collision>
    <origin rpy="0 0 0" xyz="0.25395 -0.25952 -0.1778"/>
    <geometry>
      <mesh filename="package://nararobot/meshes/LeftBwheel_1.stl" scale="0.001 0.001 0.001"/>
    </geometry>
  </collision>
</link>

<link name="RightBwheel_1">
  <inertial>
    <origin rpy="0 0 0" xyz="0.0 0.009938723135146071 5.551115123125783e-17"/>
    <mass value="38.72535292582967"/>
    <inertia ixx="0.371681" ixy="0.0" ixz="0.0" iyy="0.708374" iyz="-0.0" izz="0.371681"/>
  </inertial>
  <visual>
    <origin rpy="0 0 0" xyz="0.25395 0.25952 -0.1778"/>
    <geometry>
      <mesh filename="package://nararobot/meshes/RightBwheel_1.stl" scale="0.001 0.001 0.001"/>
    </geometry>
    <material name="silver"/>
  </visual>
  <collision>
    <origin rpy="0 0 0" xyz="0.25395 0.25952 -0.1778"/>
    <geometry>
      <mesh filename="package://nararobot/meshes/RightBwheel_1.stl" scale="0.001 0.001 0.001"/>
    </geometry>
  </collision>
</link>

<link name="RightFwheel_1">
  <inertial>
    <origin rpy="0 0 0" xyz="4.266583050194228e-07 -0.040640407880343815 -3.885780586188048e-16"/>
    <mass value="18.73694827214068"/>
    <inertia ixx="0.063698" ixy="-0.0" ixz="0.0" iyy="0.115114" iyz="0.0" izz="0.063698"/>
  </inertial>
  <visual>
    <origin rpy="0 0 0" xyz="-0.254274 0.139279 -0.1143"/>
    <geometry>
      <mesh filename="package://nararobot/meshes/RightFwheel_1.stl" scale="0.001 0.001 0.001"/>
    </geometry>
    <material name="silver"/>
  </visual>
  <collision>
    <origin rpy="0 0 0" xyz="-0.254274 0.139279 -0.1143"/>
    <geometry>
      <mesh filename="package://nararobot/meshes/RightFwheel_1.stl" scale="0.001 0.001 0.001"/>
    </geometry>
  </collision>
</link>

<link name="LeftFwheel_1">
  <inertial>
    <origin rpy="0 0 0" xyz="4.266583051304451e-07 0.04064040788034384 -3.885780586188048e-16"/>
    <mass value="18.736948272140655"/>
    <inertia ixx="0.063698" ixy="0.0" ixz="-0.0" iyy="0.115114" iyz="-0.0" izz="0.063698"/>
  </inertial>
  <visual>
    <origin rpy="0 0 0" xyz="-0.254274 -0.144579 -0.1143"/>
    <geometry>
      <mesh filename="package://nararobot/meshes/LeftFwheel_1.stl" scale="0.001 0.001 0.001"/>
    </geometry>
    <material name="silver"/>
  </visual>
  <collision>
    <origin rpy="0 0 0" xyz="-0.254274 -0.144579 -0.1143"/>
    <geometry>
      <mesh filename="package://nararobot/meshes/LeftFwheel_1.stl" scale="0.001 0.001 0.001"/>
    </geometry>
  </collision>
</link>

<link name="RightCaster_1">
  <inertial>
    <origin rpy="0 0 0" xyz="-0.02409230820648961 -4.0788036120842364e-07 -0.07195970022641951"/>
    <mass value="0.39134523651595843"/>
    <inertia ixx="0.001498" ixy="0.0" ixz="-0.000297" iyy="0.001071" iyz="0.0" izz="0.00083"/>
  </inertial>
  <visual>
    <origin rpy="0 0 0" xyz="-0.296874 0.179919 -0.26"/>
    <geometry>
      <mesh filename="package://nararobot/meshes/RightCaster_1.stl" scale="0.001 0.001 0.001"/>
    </geometry>
    <material name="silver"/>
  </visual>
  <collision>
    <origin rpy="0 0 0" xyz="-0.296874 0.179919 -0.26"/>
    <geometry>
      <mesh filename="package://nararobot/meshes/RightCaster_1.stl" scale="0.001 0.001 0.001"/>
    </geometry>
  </collision>
</link>

<link name="LeftCaster_1">
  <inertial>
    <origin rpy="0 0 0" xyz="-0.024092308206489554 4.07880326652732e-07 -0.07195970022641981"/>
    <mass value="0.39134523651595965"/>
    <inertia ixx="0.001498" ixy="0.0" ixz="-0.000297" iyy="0.001071" iyz="0.0" izz="0.00083"/>
  </inertial>
  <visual>
    <origin rpy="0 0 0" xyz="-0.296874 -0.185219 -0.26"/>
    <geometry>
      <mesh filename="package://nararobot/meshes/LeftCaster_1.stl" scale="0.001 0.001 0.001"/>
    </geometry>
    <material name="silver"/>
  </visual>
  <collision>
    <origin rpy="0 0 0" xyz="-0.296874 -0.185219 -0.26"/>
    <geometry>
      <mesh filename="package://nararobot/meshes/LeftCaster_1.stl" scale="0.001 0.001 0.001"/>
    </geometry>
  </collision>
</link>

<link name="hokuyo_link">
    <collision>
      <origin xyz="0 0 0" rpy="0 0 0"/>
      <geometry>
    <box size="0.1 0.1 0.1"/>
      </geometry>
    </collision>

    <visual>
      <origin xyz="0 0 0" rpy="0 0 0"/>
      <geometry>
        <mesh filename="package://nararobot/meshes/hokuyo.dae"/>
      </geometry>
    </visual>

    <inertial>
      <mass value="1e-5" />
      <origin xyz="0 0 0" rpy="0 0 0"/>
      <inertia ixx="1e-6" ixy="0" ixz="0" iyy="1e-6" iyz="0" izz="1e-6" />
    </inertial>
</link>

<joint name="base_footprint_joint" type="fixed">
  <origin xyz="0 0 0" rpy="0 0 0" />
  <parent link="base_footprint"/>
  <child link="base_link" />
  <axis xyz="0.0 1.0 0.0"/>
</joint>

<joint name="camera_link_joint" type="fixed">
  <origin xyz="-0.18 0 1.3" rpy="0 0 -1.57"/>
  <parent link="base_link"/>
  <child link="camera_link" />
  <axis xyz="0.0 1.0 0.0"/>
</joint>

<joint name="hokuyo_joint" type="fixed">
  <axis xyz="0 1 0" />
  <origin xyz="0.83 0 0.04" rpy="0 3.14 3.14" />
  <parent link="base_link"/>
  <child link="hokuyo_link"/>
</joint>

<joint name="Rev61" type="continuous">
  <origin rpy="0 0 0" xyz="-0.02395 0.25952 0.1778"/>
  <parent link="base_link"/>
  <child link="LeftBwheel_1"/>
  <axis xyz="0.0 1.0 0.0"/>
</joint>

<joint name="Rev62" type="continuous">
  <origin rpy="0 0 0" xyz="-0.02395 -0.25952 0.1778"/>
  <parent link="base_link"/>
  <child link="RightBwheel_1"/>
  <axis xyz="-0.0 -1.0 0.0"/>
</joint>

<joint name="Rev63" type="continuous">
  <origin rpy="0 0 0" xyz="-0.0426 0.04064 -0.1457"/>
  <parent link="RightCaster_1"/>
  <child link="RightFwheel_1"/>
  <axis xyz="-0.0 -1.0 -0.0"/>
</joint>

<joint name="Rev64" type="continuous">
  <origin rpy="0 0 0" xyz="-0.0426 -0.04064 -0.1457"/>
  <parent link="LeftCaster_1"/>
  <child link="LeftFwheel_1"/>
  <axis xyz="0.0 1.0 -0.0"/>
</joint>

<joint name="Rev65" type="continuous">
  <origin rpy="0 0 0" xyz="0.526874 -0.179919 0.26"/>
  <parent link="base_link"/>
  <child link="RightCaster_1"/>
  <axis xyz="0.0 0.0 -1.0"/>
</joint>

<joint name="Rev66" type="continuous">
  <origin rpy="0 0 0" xyz="0.526874 0.185219 0.26"/>
  <parent link="base_link"/>
  <child link="LeftCaster_1"/>
  <axis xyz="0.0 0.0 1.0"/>
</joint>

</robot>
